Workbook

Sheet Ref
B2: LS | C2: Classe
B3: 20 | C3: 1
B4: 30 | C4: 2
B5: 40 | C5: 3
B6: 50 | C6: 4
B7: 60 | C7: 5
B8: 70 | C8: 6
B9: 80 | C9: 7
B10: 90 | C10: 8
B11: 100 | C11: 9
B12: 0 | C12: Morta

Sheet Planilha6
B2: Espécie | C2: CAP 2006 | D2: CAP 2009 | E2: CAP 2012 | F2: DAP 2006 | G2: DAP 2009 | H2: DAP 2012 | K2: Classe 2006 | L2: Classe 2009 | M2: Classe 2012 | Q2: Frequências Observadas | AF2: Prognoses
B3: Ocotea pulchella | C3: 44.2 | D3: 0 | E3: 0 | F3: =IF(C3="", "", C3/PI()) -> 14.069297 | G3: =IF(D3="", "", D3/PI()) -> 0 | H3: =IF(E3="", "", E3/PI()) -> 0 | K3: =_xlfn.XLOOKUP(F3,Ref!$B$3:$B$12,Ref!$C$3:$C$12,"",1) -> 1 | L3: =_xlfn.XLOOKUP(G3,Ref!$B$3:$B$12,Ref!$C$3:$C$12,"",1) -> Morta | M3: =_xlfn.XLOOKUP(H3,Ref!$B$3:$B$12,Ref!$C$3:$C$12,"",1) -> Morta | R3: Classe | AF3: Classe | AG3: 2006 | AH3: 2009 | AI3: 2012 | AJ3: 2015 | AK3: 2018
B4: Myrsine coriacea | C4: 87.1 | D4: 94.6 | E4: 101.5 | F4: =IF(C4="", "", C4/PI()) -> 27.724791 | G4: =IF(D4="", "", D4/PI()) -> 30.112115 | H4: =IF(E4="", "", E4/PI()) -> 32.308453 | K4: =_xlfn.XLOOKUP(F4,Ref!$B$3:$B$12,Ref!$C$3:$C$12,"",1) -> 2 | L4: =_xlfn.XLOOKUP(G4,Ref!$B$3:$B$12,Ref!$C$3:$C$12,"",1) -> 3 | M4: =_xlfn.XLOOKUP(H4,Ref!$B$3:$B$12,Ref!$C$3:$C$12,"",1) -> 3 | R4: 1 | S4: 2 | T4: 3 | U4: 4 | V4: 5 | W4: 6 | X4: 7 | Y4: 8 | Z4: 9 | AF4: 1 | AG4: {=TRANSPOSE($R$5:$Z$5)} -> 1310 | AH4: {=MMULT($R$30:$Z$38,_xlfn.ANCHORARRAY(AG$4)) + $AB$14:$AB$22} -> 1315 | AI4: {=MMULT($R$30:$Z$38,_xlfn.ANCHORARRAY(AH$4)) + $AB$14:$AB$22} -> 1319.5802 | AJ4: {=MMULT($R$30:$Z$38,_xlfn.ANCHORARRAY(AI$4)) + $AB$14:$AB$22} -> 1323.7757 | AK4: {=MMULT($R$30:$Z$38,_xlfn.ANCHORARRAY(AJ$4)) + $AB$14:$AB$22} -> 1327.619
B5: Lithraea brasiliensis | C5: 74.6 | D5: 81.2 | E5: 85.1 | F5: =IF(C5="", "", C5/PI()) -> 23.745918 | G5: =IF(D5="", "", D5/PI()) -> 25.846763 | H5: =IF(E5="", "", E5/PI()) -> 27.088171 | K5: =_xlfn.XLOOKUP(F5,Ref!$B$3:$B$12,Ref!$C$3:$C$12,"",1) -> 2 | L5: =_xlfn.XLOOKUP(G5,Ref!$B$3:$B$12,Ref!$C$3:$C$12,"",1) -> 2 | M5: =_xlfn.XLOOKUP(H5,Ref!$B$3:$B$12,Ref!$C$3:$C$12,"",1) -> 2 | Q5: Y1 | R5: =COUNTIF($K$3:$K$1850,R$4) -> 1310 | S5: =COUNTIF($K$3:$K$1850,S$4) -> 230 | T5: =COUNTIF($K$3:$K$1850,T$4) -> 62 | U5: =COUNTIF($K$3:$K$1850,U$4) -> 24 | V5: =COUNTIF($K$3:$K$1850,V$4) -> 17 | W5: =COUNTIF($K$3:$K$1850,W$4) -> 19 | X5: =COUNTIF($K$3:$K$1850,X$4) -> 3 | Y5: =COUNTIF($K$3:$K$1850,Y$4) -> 0 | Z5: =COUNTIF($K$3:$K$1850,Z$4) -> 0 | AF5: 2 | AG5: 230 | AH5: 277 | AI5: 320.35936 | AJ5: 360.41738 | AK5: 397.47937 | AP5: Matriz Identidade
B6: Gymnanthes klotzschiana | C6: 34.4 | D6: 35.3 | E6: 36.8 | F6: =IF(C6="", "", C6/PI()) -> 10.94986 | G6: =IF(D6="", "", D6/PI()) -> 11.236339 | H6: =IF(E6="", "", E6/PI()) -> 11.713804 | K6: =_xlfn.XLOOKUP(F6,Ref!$B$3:$B$12,Ref!$C$3:$C$12,"",1) -> 1 | L6: =_xlfn.XLOOKUP(G6,Ref!$B$3:$B$12,Ref!$C$3:$C$12,"",1) -> 1 | M6: =_xlfn.XLOOKUP(H6,Ref!$B$3:$B$12,Ref!$C$3:$C$12,"",1) -> 1 | Q6: Y2 | R6: =COUNTIF($L$3:$L$1850,R$4) -> 1315 | S6: =COUNTIF($L$3:$L$1850,S$4) -> 277 | T6: =COUNTIF($L$3:$L$1850,T$4) -> 75 | U6: =COUNTIF($L$3:$L$1850,U$4) -> 21 | V6: =COUNTIF($L$3:$L$1850,V$4) -> 18 | W6: =COUNTIF($L$3:$L$1850,W$4) -> 21 | X6: =COUNTIF($L$3:$L$1850,X$4) -> 3 | Y6: =COUNTIF($L$3:$L$1850,Y$4) -> 1 | Z6: =COUNTIF($L$3:$L$1850,Z$4) -> 0 | AF6: 3 | AG6: 62 | AH6: 75 | AI6: 90.640533 | AJ6: 108.54057 | AK6: 128.36112 | AP6: 1 | AQ6: 0 | AR6: 0 | AS6: 0 | AT6: 0 | AU6: 0 | AV6: 0 | AW6: 0 | AX6: 0
B7: Duranta vestita | C7: 37.4 | D7: 37.4 | E7: 0 | F7: =IF(C7="", "", C7/PI()) -> 11.90479 | G7: =IF(D7="", "", D7/PI()) -> 11.90479 | H7: =IF(E7="", "", E7/PI()) -> 0 | K7: =_xlfn.XLOOKUP(F7,Ref!$B$3:$B$12,Ref!$C$3:$C$12,"",1) -> 1 | L7: =_xlfn.XLOOKUP(G7,Ref!$B$3:$B$12,Ref!$C$3:$C$12,"",1) -> 1 | M7: =_xlfn.XLOOKUP(H7,Ref!$B$3:$B$12,Ref!$C$3:$C$12,"",1) -> Morta | Q7: Y3 | R7: =COUNTIF($M$3:$M$1850,R$4) -> 1276 | S7: =COUNTIF($M$3:$M$1850,S$4) -> 295 | T7: =COUNTIF($M$3:$M$1850,T$4) -> 89 | U7: =COUNTIF($M$3:$M$1850,U$4) -> 23 | V7: =COUNTIF($M$3:$M$1850,V$4) -> 19 | W7: =COUNTIF($M$3:$M$1850,W$4) -> 16 | X7: =COUNTIF($M$3:$M$1850,X$4) -> 9 | Y7: =COUNTIF($M$3:$M$1850,Y$4) -> 2 | Z7: =COUNTIF($M$3:$M$1850,Z$4) -> 0 | AF7: 4 | AG7: 24 | AH7: 21 | AI7: 18.709677 | AJ7: 17.053342 | AK7: 15.961773 | AP7: 0 | AQ7: 1 | AR7: 0 | AS7: 0 | AT7: 0 | AU7: 0 | AV7: 0 | AW7: 0 | AX7: 0
B8: Duranta vestita | E8: 34 | F8: =IF(C8="", "", C8/PI()) | G8: =IF(D8="", "", D8/PI()) | H8: =IF(E8="", "", E8/PI()) -> 10.822536 | K8: =_xlfn.XLOOKUP(F8,Ref!$B$3:$B$12,Ref!$C$3:$C$12,"",1) | L8: =_xlfn.XLOOKUP(G8,Ref!$B$3:$B$12,Ref!$C$3:$C$12,"",1) | M8: =_xlfn.XLOOKUP(H8,Ref!$B$3:$B$12,Ref!$C$3:$C$12,"",1) -> 1 | AF8: 5 | AG8: 17 | AH8: 18 | AI8: 18.323529 | AJ8: 18.208245 | AK8: 17.837249 | AP8: 0 | AQ8: 0 | AR8: 1 | AS8: 0 | AT8: 0 | AU8: 0 | AV8: 0 | AW8: 0 | AX8: 0
B9: Schinus terebinthifolia | C9: 74.8 | D9: 82.5 | E9: 87.5 | F9: =IF(C9="", "", C9/PI()) -> 23.809579 | G9: =IF(D9="", "", D9/PI()) -> 26.260566 | H9: =IF(E9="", "", E9/PI()) -> 27.852115 | K9: =_xlfn.XLOOKUP(F9,Ref!$B$3:$B$12,Ref!$C$3:$C$12,"",1) -> 2 | L9: =_xlfn.XLOOKUP(G9,Ref!$B$3:$B$12,Ref!$C$3:$C$12,"",1) -> 2 | M9: =_xlfn.XLOOKUP(H9,Ref!$B$3:$B$12,Ref!$C$3:$C$12,"",1) -> 2 | AF9: 6 | AG9: 19 | AH9: 21 | AI9: 23.071207 | AJ9: 25.090497 | AK9: 26.983165 | AP9: 0 | AQ9: 0 | AR9: 0 | AS9: 1 | AT9: 0 | AU9: 0 | AV9: 0 | AW9: 0 | AX9: 0
B10: Schinus terebinthifolia | C10: 52 | D10: 55.3 | E10: 57.2 | F10: =IF(C10="", "", C10/PI()) -> 16.552114 | G10: =IF(D10="", "", D10/PI()) -> 17.602537 | H10: =IF(E10="", "", E10/PI()) -> 18.207325 | K10: =_xlfn.XLOOKUP(F10,Ref!$B$3:$B$12,Ref!$C$3:$C$12,"",1) -> 1 | L10: =_xlfn.XLOOKUP(G10,Ref!$B$3:$B$12,Ref!$C$3:$C$12,"",1) -> 1 | M10: =_xlfn.XLOOKUP(H10,Ref!$B$3:$B$12,Ref!$C$3:$C$12,"",1) -> 1 | AF10: 7 | AG10: 3 | AH10: 3 | AI10: 3.1052632 | AJ10: 3.2844495 | AK10: 3.5101855 | AP10: 0 | AQ10: 0 | AR10: 0 | AS10: 0 | AT10: 1 | AU10: 0 | AV10: 0 | AW10: 0 | AX10: 0
B11: Allophylus edulis | C11: 36.7 | D11: 39 | E11: 42.5 | F11: =IF(C11="", "", C11/PI()) -> 11.681973 | G11: =IF(D11="", "", D11/PI()) -> 12.414086 | H11: =IF(E11="", "", E11/PI()) -> 13.52817 | K11: =_xlfn.XLOOKUP(F11,Ref!$B$3:$B$12,Ref!$C$3:$C$12,"",1) -> 1 | L11: =_xlfn.XLOOKUP(G11,Ref!$B$3:$B$12,Ref!$C$3:$C$12,"",1) -> 1 | M11: =_xlfn.XLOOKUP(H11,Ref!$B$3:$B$12,Ref!$C$3:$C$12,"",1) -> 1 | AF11: 8 | AG11: 0 | AH11: 1 | AI11: 1.5 | AJ11: 1.7850877 | AK11: 1.9873604 | AP11: 0 | AQ11: 0 | AR11: 0 | AS11: 0 | AT11: 0 | AU11: 1 | AV11: 0 | AW11: 0 | AX11: 0
B12: Schinus terebinthifolia | C12: 90.5 | D12: 93.5 | E12: 104.6 | F12: =IF(C12="", "", C12/PI()) -> 28.807045 | G12: =IF(D12="", "", D12/PI()) -> 29.761974 | H12: =IF(E12="", "", E12/PI()) -> 33.295214 | K12: =_xlfn.XLOOKUP(F12,Ref!$B$3:$B$12,Ref!$C$3:$C$12,"",1) -> 2 | L12: =_xlfn.XLOOKUP(G12,Ref!$B$3:$B$12,Ref!$C$3:$C$12,"",1) -> 2 | M12: =_xlfn.XLOOKUP(H12,Ref!$B$3:$B$12,Ref!$C$3:$C$12,"",1) -> 3 | Q12: Matriz de Transições 2006-2009 (Mudanças Absolutas) | AB12: Ingresso | AF12: 9 | AG12: 0 | AH12: 0 | AI12: 0 | AJ12: 0 | AK12: 0 | AP12: 0 | AQ12: 0 | AR12: 0 | AS12: 0 | AT12: 0 | AU12: 0 | AV12: 1 | AW12: 0 | AX12: 0
B13: Schinus terebinthifolia | C13: 55 | D13: 59.5 | E13: 62.7 | F13: =IF(C13="", "", C13/PI()) -> 17.507044 | G13: =IF(D13="", "", D13/PI()) -> 18.939438 | H13: =IF(E13="", "", E13/PI()) -> 19.95803 | K13: =_xlfn.XLOOKUP(F13,Ref!$B$3:$B$12,Ref!$C$3:$C$12,"",1) -> 1 | L13: =_xlfn.XLOOKUP(G13,Ref!$B$3:$B$12,Ref!$C$3:$C$12,"",1) -> 1 | M13: =_xlfn.XLOOKUP(H13,Ref!$B$3:$B$12,Ref!$C$3:$C$12,"",1) -> 1 | Q13: Classe | R13: 1 | S13: 2 | T13: 3 | U13: 4 | V13: 5 | W13: 6 | X13: 7 | Y13: 8 | Z13: 9 | AP13: 0 | AQ13: 0 | AR13: 0 | AS13: 0 | AT13: 0 | AU13: 0 | AV13: 0 | AW13: 1 | AX13: 0
B14: Schinus terebinthifolia | C14: 65.2 | D14: 73.2 | E14: 76 | F14: =IF(C14="", "", C14/PI()) -> 20.753805 | G14: =IF(D14="", "", D14/PI()) -> 23.300284 | H14: =IF(E14="", "", E14/PI()) -> 24.191551 | K14: =_xlfn.XLOOKUP(F14,Ref!$B$3:$B$12,Ref!$C$3:$C$12,"",1) -> 2 | L14: =_xlfn.XLOOKUP(G14,Ref!$B$3:$B$12,Ref!$C$3:$C$12,"",1) -> 2 | M14: =_xlfn.XLOOKUP(H14,Ref!$B$3:$B$12,Ref!$C$3:$C$12,"",1) -> 2 | Q14: 1 | R14: =COUNTIFS($K$3:$K$1850,R$13,$L$3:$L$1850,$Q14) -> 1200 | S14: =COUNTIFS($K$3:$K$1850,S$13,$L$3:$L$1850,$Q14) -> 0 | T14: =COUNTIFS($K$3:$K$1850,T$13,$L$3:$L$1850,$Q14) -> 0 | U14: =COUNTIFS($K$3:$K$1850,U$13,$L$3:$L$1850,$Q14) -> 0 | V14: =COUNTIFS($K$3:$K$1850,V$13,$L$3:$L$1850,$Q14) -> 0 | W14: =COUNTIFS($K$3:$K$1850,W$13,$L$3:$L$1850,$Q14) -> 0 | X14: =COUNTIFS($K$3:$K$1850,X$13,$L$3:$L$1850,$Q14) -> 0 | Y14: =COUNTIFS($K$3:$K$1850,Y$13,$L$3:$L$1850,$Q14) -> 0 | Z14: =COUNTIFS($K$3:$K$1850,Z$13,$L$3:$L$1850,$Q14) -> 0 | AB14: =COUNTIFS($K$3:$K$1850,"",$L$3:$L$1850,$Q14) -> 115 | AP14: 0 | AQ14: 0 | AR14: 0 | AS14: 0 | AT14: 0 | AU14: 0 | AV14: 0 | AW14: 0 | AX14: 1
B15: Schinus terebinthifolia | C15: 53 | D15: 56.6 | E15: 58.7 | F15: =IF(C15="", "", C15/PI()) -> 16.870424 | G15: =IF(D15="", "", D15/PI()) -> 18.01634 | H15: =IF(E15="", "", E15/PI()) -> 18.68479 | K15: =_xlfn.XLOOKUP(F15,Ref!$B$3:$B$12,Ref!$C$3:$C$12,"",1) -> 1 | L15: =_xlfn.XLOOKUP(G15,Ref!$B$3:$B$12,Ref!$C$3:$C$12,"",1) -> 1 | M15: =_xlfn.XLOOKUP(H15,Ref!$B$3:$B$12,Ref!$C$3:$C$12,"",1) -> 1 | Q15: 2 | R15: =COUNTIFS($K$3:$K$1850,R$13,$L$3:$L$1850,$Q15) -> 62 | S15: =COUNTIFS($K$3:$K$1850,S$13,$L$3:$L$1850,$Q15) -> 210 | T15: =COUNTIFS($K$3:$K$1850,T$13,$L$3:$L$1850,$Q15) -> 1 | U15: =COUNTIFS($K$3:$K$1850,U$13,$L$3:$L$1850,$Q15) -> 0 | V15: =COUNTIFS($K$3:$K$1850,V$13,$L$3:$L$1850,$Q15) -> 0 | W15: =COUNTIFS($K$3:$K$1850,W$13,$L$3:$L$1850,$Q15) -> 0 | X15: =COUNTIFS($K$3:$K$1850,X$13,$L$3:$L$1850,$Q15) -> 0 | Y15: =COUNTIFS($K$3:$K$1850,Y$13,$L$3:$L$1850,$Q15) -> 0 | Z15: =COUNTIFS($K$3:$K$1850,Z$13,$L$3:$L$1850,$Q15) -> 0 | AB15: =COUNTIFS($K$3:$K$1850,"",$L$3:$L$1850,$Q15) -> 4
B16: Schinus terebinthifolia | C16: 42 | D16: 44 | E16: 46.8 | F16: =IF(C16="", "", C16/PI()) -> 13.369015 | G16: =IF(D16="", "", D16/PI()) -> 14.005635 | H16: =IF(E16="", "", E16/PI()) -> 14.896903 | K16: =_xlfn.XLOOKUP(F16,Ref!$B$3:$B$12,Ref!$C$3:$C$12,"",1) -> 1 | L16: =_xlfn.XLOOKUP(G16,Ref!$B$3:$B$12,Ref!$C$3:$C$12,"",1) -> 1 | M16: =_xlfn.XLOOKUP(H16,Ref!$B$3:$B$12,Ref!$C$3:$C$12,"",1) -> 1 | Q16: 3 | R16: =COUNTIFS($K$3:$K$1850,R$13,$L$3:$L$1850,$Q16) -> 0 | S16: =COUNTIFS($K$3:$K$1850,S$13,$L$3:$L$1850,$Q16) -> 16 | T16: =COUNTIFS($K$3:$K$1850,T$13,$L$3:$L$1850,$Q16) -> 59 | U16: =COUNTIFS($K$3:$K$1850,U$13,$L$3:$L$1850,$Q16) -> 0 | V16: =COUNTIFS($K$3:$K$1850,V$13,$L$3:$L$1850,$Q16) -> 0 | W16: =COUNTIFS($K$3:$K$1850,W$13,$L$3:$L$1850,$Q16) -> 0 | X16: =COUNTIFS($K$3:$K$1850,X$13,$L$3:$L$1850,$Q16) -> 0 | Y16: =COUNTIFS($K$3:$K$1850,Y$13,$L$3:$L$1850,$Q16) -> 0 | Z16: =COUNTIFS($K$3:$K$1850,Z$13,$L$3:$L$1850,$Q16) -> 0 | AB16: =COUNTIFS($K$3:$K$1850,"",$L$3:$L$1850,$Q16) -> 0
B17: Lithraea brasiliensis | C17: 76.3 | D17: 76.3 | E17: 75.2 | F17: =IF(C17="", "", C17/PI()) -> 24.287044 | G17: =IF(D17="", "", D17/PI()) -> 24.287044 | H17: =IF(E17="", "", E17/PI()) -> 23.936903 | K17: =_xlfn.XLOOKUP(F17,Ref!$B$3:$B$12,Ref!$C$3:$C$12,"",1) -> 2 | L17: =_xlfn.XLOOKUP(G17,Ref!$B$3:$B$12,Ref!$C$3:$C$12,"",1) -> 2 | M17: =_xlfn.XLOOKUP(H17,Ref!$B$3:$B$12,Ref!$C$3:$C$12,"",1) -> 2 | Q17: 4 | R17: =COUNTIFS($K$3:$K$1850,R$13,$L$3:$L$1850,$Q17) -> 0 | S17: =COUNTIFS($K$3:$K$1850,S$13,$L$3:$L$1850,$Q17) -> 0 | T17: =COUNTIFS($K$3:$K$1850,T$13,$L$3:$L$1850,$Q17) -> 1 | U17: =COUNTIFS($K$3:$K$1850,U$13,$L$3:$L$1850,$Q17) -> 20 | V17: =COUNTIFS($K$3:$K$1850,V$13,$L$3:$L$1850,$Q17) -> 0 | W17: =COUNTIFS($K$3:$K$1850,W$13,$L$3:$L$1850,$Q17) -> 0 | X17: =COUNTIFS($K$3:$K$1850,X$13,$L$3:$L$1850,$Q17) -> 0 | Y17: =COUNTIFS($K$3:$K$1850,Y$13,$L$3:$L$1850,$Q17) -> 0 | Z17: =COUNTIFS($K$3:$K$1850,Z$13,$L$3:$L$1850,$Q17) -> 0 | AB17: =COUNTIFS($K$3:$K$1850,"",$L$3:$L$1850,$Q17) -> 0 | AF17: Frequências Observadas | AP17: Id - M
B18: Schinus terebinthifolia | C18: 37 | D18: 42.9 | E18: 46 | F18: =IF(C18="", "", C18/PI()) -> 11.777466 | G18: =IF(D18="", "", D18/PI()) -> 13.655494 | H18: =IF(E18="", "", E18/PI()) -> 14.642255 | K18: =_xlfn.XLOOKUP(F18,Ref!$B$3:$B$12,Ref!$C$3:$C$12,"",1) -> 1 | L18: =_xlfn.XLOOKUP(G18,Ref!$B$3:$B$12,Ref!$C$3:$C$12,"",1) -> 1 | M18: =_xlfn.XLOOKUP(H18,Ref!$B$3:$B$12,Ref!$C$3:$C$12,"",1) -> 1 | Q18: 5 | R18: =COUNTIFS($K$3:$K$1850,R$13,$L$3:$L$1850,$Q18) -> 0 | S18: =COUNTIFS($K$3:$K$1850,S$13,$L$3:$L$1850,$Q18) -> 0 | T18: =COUNTIFS($K$3:$K$1850,T$13,$L$3:$L$1850,$Q18) -> 0 | U18: =COUNTIFS($K$3:$K$1850,U$13,$L$3:$L$1850,$Q18) -> 4 | V18: =COUNTIFS($K$3:$K$1850,V$13,$L$3:$L$1850,$Q18) -> 14 | W18: =COUNTIFS($K$3:$K$1850,W$13,$L$3:$L$1850,$Q18) -> 0 | X18: =COUNTIFS($K$3:$K$1850,X$13,$L$3:$L$1850,$Q18) -> 0 | Y18: =COUNTIFS($K$3:$K$1850,Y$13,$L$3:$L$1850,$Q18) -> 0 | Z18: =COUNTIFS($K$3:$K$1850,Z$13,$L$3:$L$1850,$Q18) -> 0 | AB18: =COUNTIFS($K$3:$K$1850,"",$L$3:$L$1850,$Q18) -> 0 | AF18: Classe | AG18: 2006 | AH18: 2009 | AI18: 2012 | AK18: Resíduo | AL18: RQME | AP18: {=AP6:AX14-R30:Z38} -> 0.083969466 | AQ18: 0 | AR18: 0 | AS18: 0 | AT18: 0 | AU18: 0 | AV18: 0 | AW18: 0 | AX18: 0
B19: Schinus terebinthifolia | C19: 34.7 | D19: 39.6 | E19: 43.3 | F19: =IF(C19="", "", C19/PI()) -> 11.045353 | G19: =IF(D19="", "", D19/PI()) -> 12.605071 | H19: =IF(E19="", "", E19/PI()) -> 13.782818 | K19: =_xlfn.XLOOKUP(F19,Ref!$B$3:$B$12,Ref!$C$3:$C$12,"",1) -> 1 | L19: =_xlfn.XLOOKUP(G19,Ref!$B$3:$B$12,Ref!$C$3:$C$12,"",1) -> 1 | M19: =_xlfn.XLOOKUP(H19,Ref!$B$3:$B$12,Ref!$C$3:$C$12,"",1) -> 1 | Q19: 6 | R19: =COUNTIFS($K$3:$K$1850,R$13,$L$3:$L$1850,$Q19) -> 0 | S19: =COUNTIFS($K$3:$K$1850,S$13,$L$3:$L$1850,$Q19) -> 0 | T19: =COUNTIFS($K$3:$K$1850,T$13,$L$3:$L$1850,$Q19) -> 0 | U19: =COUNTIFS($K$3:$K$1850,U$13,$L$3:$L$1850,$Q19) -> 0 | V19: =COUNTIFS($K$3:$K$1850,V$13,$L$3:$L$1850,$Q19) -> 3 | W19: =COUNTIFS($K$3:$K$1850,W$13,$L$3:$L$1850,$Q19) -> 18 | X19: =COUNTIFS($K$3:$K$1850,X$13,$L$3:$L$1850,$Q19) -> 0 | Y19: =COUNTIFS($K$3:$K$1850,Y$13,$L$3:$L$1850,$Q19) -> 0 | Z19: =COUNTIFS($K$3:$K$1850,Z$13,$L$3:$L$1850,$Q19) -> 0 | AB19: =COUNTIFS($K$3:$K$1850,"",$L$3:$L$1850,$Q19) -> 0 | AF19: 1 | AG19: {=TRANSPOSE($R$5:$Z$5)} -> 1310 | AH19: {=TRANSPOSE(R6:Z6)} -> 1315 | AI19: {=TRANSPOSE(R7:Z7)} -> 1276 | AK19: =AI19-AI4 -> -43.580153 | AL19: =SQRT(AVERAGE(SUMSQ(AK19:AK26))) -> 51.467297 | AP19: -0.047328244 | AQ19: 0.086956522 | AR19: -0.016129032 | AS19: 0 | AT19: 0 | AU19: 0 | AV19: 0 | AW19: 0 | AX19: 0
B20: Schinus terebinthifolia | C20: 59.2 | D20: 64.2 | E20: 67.7 | F20: =IF(C20="", "", C20/PI()) -> 18.843945 | G20: =IF(D20="", "", D20/PI()) -> 20.435495 | H20: =IF(E20="", "", E20/PI()) -> 21.549579 | K20: =_xlfn.XLOOKUP(F20,Ref!$B$3:$B$12,Ref!$C$3:$C$12,"",1) -> 1 | L20: =_xlfn.XLOOKUP(G20,Ref!$B$3:$B$12,Ref!$C$3:$C$12,"",1) -> 2 | M20: =_xlfn.XLOOKUP(H20,Ref!$B$3:$B$12,Ref!$C$3:$C$12,"",1) -> 2 | Q20: 7 | R20: =COUNTIFS($K$3:$K$1850,R$13,$L$3:$L$1850,$Q20) -> 0 | S20: =COUNTIFS($K$3:$K$1850,S$13,$L$3:$L$1850,$Q20) -> 0 | T20: =COUNTIFS($K$3:$K$1850,T$13,$L$3:$L$1850,$Q20) -> 0 | U20: =COUNTIFS($K$3:$K$1850,U$13,$L$3:$L$1850,$Q20) -> 0 | V20: =COUNTIFS($K$3:$K$1850,V$13,$L$3:$L$1850,$Q20) -> 0 | W20: =COUNTIFS($K$3:$K$1850,W$13,$L$3:$L$1850,$Q20) -> 1 | X20: =COUNTIFS($K$3:$K$1850,X$13,$L$3:$L$1850,$Q20) -> 2 | Y20: =COUNTIFS($K$3:$K$1850,Y$13,$L$3:$L$1850,$Q20) -> 0 | Z20: =COUNTIFS($K$3:$K$1850,Z$13,$L$3:$L$1850,$Q20) -> 0 | AB20: =COUNTIFS($K$3:$K$1850,"",$L$3:$L$1850,$Q20) -> 0 | AF20: 2 | AG20: 230 | AH20: 277 | AI20: 295 | AK20: =AI20-AI5 -> -25.359362 | AP20: 0 | AQ20: -0.069565217 | AR20: 0.048387097 | AS20: 0 | AT20: 0 | AU20: 0 | AV20: 0 | AW20: 0 | AX20: 0
B21: Ocotea puberula | C21: 47.7 | D21: 59.2 | E21: 65.7 | F21: =IF(C21="", "", C21/PI()) -> 15.183382 | G21: =IF(D21="", "", D21/PI()) -> 18.843945 | H21: =IF(E21="", "", E21/PI()) -> 20.91296 | K21: =_xlfn.XLOOKUP(F21,Ref!$B$3:$B$12,Ref!$C$3:$C$12,"",1) -> 1 | L21: =_xlfn.XLOOKUP(G21,Ref!$B$3:$B$12,Ref!$C$3:$C$12,"",1) -> 1 | M21: =_xlfn.XLOOKUP(H21,Ref!$B$3:$B$12,Ref!$C$3:$C$12,"",1) -> 2 | Q21: 8 | R21: =COUNTIFS($K$3:$K$1850,R$13,$L$3:$L$1850,$Q21) -> 0 | S21: =COUNTIFS($K$3:$K$1850,S$13,$L$3:$L$1850,$Q21) -> 0 | T21: =COUNTIFS($K$3:$K$1850,T$13,$L$3:$L$1850,$Q21) -> 0 | U21: =COUNTIFS($K$3:$K$1850,U$13,$L$3:$L$1850,$Q21) -> 0 | V21: =COUNTIFS($K$3:$K$1850,V$13,$L$3:$L$1850,$Q21) -> 0 | W21: =COUNTIFS($K$3:$K$1850,W$13,$L$3:$L$1850,$Q21) -> 0 | X21: =COUNTIFS($K$3:$K$1850,X$13,$L$3:$L$1850,$Q21) -> 1 | Y21: =COUNTIFS($K$3:$K$1850,Y$13,$L$3:$L$1850,$Q21) -> 0 | Z21: =COUNTIFS($K$3:$K$1850,Z$13,$L$3:$L$1850,$Q21) -> 0 | AB21: =COUNTIFS($K$3:$K$1850,"",$L$3:$L$1850,$Q21) -> 0 | AF21: 3 | AG21: 62 | AH21: 75 | AI21: 89 | AK21: =AI21-AI6 -> -1.640533 | AP21: 0 | AQ21: 0 | AR21: -0.016129032 | AS21: 0.16666667 | AT21: 0 | AU21: 0 | AV21: 0 | AW21: 0 | AX21: 0
B22: Schinus terebinthifolia | C22: 43.4 | D22: 59.8 | E22: 68.3 | F22: =IF(C22="", "", C22/PI()) -> 13.814649 | G22: =IF(D22="", "", D22/PI()) -> 19.034931 | H22: =IF(E22="", "", E22/PI()) -> 21.740565 | K22: =_xlfn.XLOOKUP(F22,Ref!$B$3:$B$12,Ref!$C$3:$C$12,"",1) -> 1 | L22: =_xlfn.XLOOKUP(G22,Ref!$B$3:$B$12,Ref!$C$3:$C$12,"",1) -> 1 | M22: =_xlfn.XLOOKUP(H22,Ref!$B$3:$B$12,Ref!$C$3:$C$12,"",1) -> 2 | Q22: 9 | R22: =COUNTIFS($K$3:$K$1850,R$13,$L$3:$L$1850,$Q22) -> 0 | S22: =COUNTIFS($K$3:$K$1850,S$13,$L$3:$L$1850,$Q22) -> 0 | T22: =COUNTIFS($K$3:$K$1850,T$13,$L$3:$L$1850,$Q22) -> 0 | U22: =COUNTIFS($K$3:$K$1850,U$13,$L$3:$L$1850,$Q22) -> 0 | V22: =COUNTIFS($K$3:$K$1850,V$13,$L$3:$L$1850,$Q22) -> 0 | W22: =COUNTIFS($K$3:$K$1850,W$13,$L$3:$L$1850,$Q22) -> 0 | X22: =COUNTIFS($K$3:$K$1850,X$13,$L$3:$L$1850,$Q22) -> 0 | Y22: =COUNTIFS($K$3:$K$1850,Y$13,$L$3:$L$1850,$Q22) -> 0 | Z22: =COUNTIFS($K$3:$K$1850,Z$13,$L$3:$L$1850,$Q22) -> 0 | AB22: =COUNTIFS($K$3:$K$1850,"",$L$3:$L$1850,$Q22) -> 0 | AF22: 4 | AG22: 24 | AH22: 21 | AI22: 23 | AK22: =AI22-AI7 -> 4.2903226 | AP22: 0 | AQ22: 0 | AR22: 0 | AS22: -0.16666667 | AT22: 0.17647059 | AU22: 0 | AV22: 0 | AW22: 0 | AX22: 0
B23: Luehea divaricata | C23: 53.5 | D23: 55.3 | E23: 56 | F23: =IF(C23="", "", C23/PI()) -> 17.029579 | G23: =IF(D23="", "", D23/PI()) -> 17.602537 | H23: =IF(E23="", "", E23/PI()) -> 17.825354 | K23: =_xlfn.XLOOKUP(F23,Ref!$B$3:$B$12,Ref!$C$3:$C$12,"",1) -> 1 | L23: =_xlfn.XLOOKUP(G23,Ref!$B$3:$B$12,Ref!$C$3:$C$12,"",1) -> 1 | M23: =_xlfn.XLOOKUP(H23,Ref!$B$3:$B$12,Ref!$C$3:$C$12,"",1) -> 1 | AF23: 5 | AG23: 17 | AH23: 18 | AI23: 19 | AK23: =AI23-AI8 -> 0.67647059 | AP23: 0 | AQ23: 0 | AR23: 0 | AS23: 0 | AT23: -0.17647059 | AU23: 0.052631579 | AV23: 0 | AW23: 0 | AX23: 0
B24: Schinus terebinthifolia | C24: 42.7 | D24: 44 | E24: 44.2 | F24: =IF(C24="", "", C24/PI()) -> 13.591832 | G24: =IF(D24="", "", D24/PI()) -> 14.005635 | H24: =IF(E24="", "", E24/PI()) -> 14.069297 | K24: =_xlfn.XLOOKUP(F24,Ref!$B$3:$B$12,Ref!$C$3:$C$12,"",1) -> 1 | L24: =_xlfn.XLOOKUP(G24,Ref!$B$3:$B$12,Ref!$C$3:$C$12,"",1) -> 1 | M24: =_xlfn.XLOOKUP(H24,Ref!$B$3:$B$12,Ref!$C$3:$C$12,"",1) -> 1 | AF24: 6 | AG24: 19 | AH24: 21 | AI24: 16 | AK24: =AI24-AI9 -> -7.0712074 | AP24: 0 | AQ24: 0 | AR24: 0 | AS24: 0 | AT24: 0 | AU24: -0.052631579 | AV24: 0.33333333 | AW24: 0 | AX24: 0
B25: Dahlstedtia floribunda | E25: 36.5 | F25: =IF(C25="", "", C25/PI()) | G25: =IF(D25="", "", D25/PI()) | H25: =IF(E25="", "", E25/PI()) -> 11.618311 | K25: =_xlfn.XLOOKUP(F25,Ref!$B$3:$B$12,Ref!$C$3:$C$12,"",1) | L25: =_xlfn.XLOOKUP(G25,Ref!$B$3:$B$12,Ref!$C$3:$C$12,"",1) | M25: =_xlfn.XLOOKUP(H25,Ref!$B$3:$B$12,Ref!$C$3:$C$12,"",1) -> 1 | AF25: 7 | AG25: 3 | AH25: 3 | AI25: 9 | AK25: =AI25-AI10 -> 5.8947368 | AP25: 0 | AQ25: 0 | AR25: 0 | AS25: 0 | AT25: 0 | AU25: 0 | AV25: -0.33333333 | AW25: 0.5 | AX25: 0
B26: Ocotea puberula | E26: 35.5 | F26: =IF(C26="", "", C26/PI()) | G26: =IF(D26="", "", D26/PI()) | H26: =IF(E26="", "", E26/PI()) -> 11.300001 | K26: =_xlfn.XLOOKUP(F26,Ref!$B$3:$B$12,Ref!$C$3:$C$12,"",1) | L26: =_xlfn.XLOOKUP(G26,Ref!$B$3:$B$12,Ref!$C$3:$C$12,"",1) | M26: =_xlfn.XLOOKUP(H26,Ref!$B$3:$B$12,Ref!$C$3:$C$12,"",1) -> 1 | AF26: 8 | AG26: 0 | AH26: 1 | AI26: 2 | AK26: =AI26-AI11 -> 0.5 | AP26: 0 | AQ26: 0 | AR26: 0 | AS26: 0 | AT26: 0 | AU26: 0 | AV26: 0 | AW26: 0 | AX26: 1
B27: Schinus terebinthifolia | C27: 57.7 | D27: 60.2 | E27: 61.8 | F27: =IF(C27="", "", C27/PI()) -> 18.36648 | G27: =IF(D27="", "", D27/PI()) -> 19.162255 | H27: =IF(E27="", "", E27/PI()) -> 19.671551 | K27: =_xlfn.XLOOKUP(F27,Ref!$B$3:$B$12,Ref!$C$3:$C$12,"",1) -> 1 | L27: =_xlfn.XLOOKUP(G27,Ref!$B$3:$B$12,Ref!$C$3:$C$12,"",1) -> 1 | M27: =_xlfn.XLOOKUP(H27,Ref!$B$3:$B$12,Ref!$C$3:$C$12,"",1) -> 1 | AF27: 9 | AG27: 0 | AH27: 0 | AI27: 0
B28: Schinus terebinthifolia | C28: 34 | D28: 38.5 | E28: 40.3 | F28: =IF(C28="", "", C28/PI()) -> 10.822536 | G28: =IF(D28="", "", D28/PI()) -> 12.254931 | H28: =IF(E28="", "", E28/PI()) -> 12.827888 | K28: =_xlfn.XLOOKUP(F28,Ref!$B$3:$B$12,Ref!$C$3:$C$12,"",1) -> 1 | L28: =_xlfn.XLOOKUP(G28,Ref!$B$3:$B$12,Ref!$C$3:$C$12,"",1) -> 1 | M28: =_xlfn.XLOOKUP(H28,Ref!$B$3:$B$12,Ref!$C$3:$C$12,"",1) -> 1 | Q28: Matriz de Transições 2006-2009 (Probabilidades)
B29: Schinus terebinthifolia | C29: 44.7 | D29: 47.8 | E29: 47.5 | F29: =IF(C29="", "", C29/PI()) -> 14.228452 | G29: =IF(D29="", "", D29/PI()) -> 15.215213 | H29: =IF(E29="", "", E29/PI()) -> 15.11972 | K29: =_xlfn.XLOOKUP(F29,Ref!$B$3:$B$12,Ref!$C$3:$C$12,"",1) -> 1 | L29: =_xlfn.XLOOKUP(G29,Ref!$B$3:$B$12,Ref!$C$3:$C$12,"",1) -> 1 | M29: =_xlfn.XLOOKUP(H29,Ref!$B$3:$B$12,Ref!$C$3:$C$12,"",1) -> 1 | Q29: Classe | R29: 1 | S29: 2 | T29: 3 | U29: 4 | V29: 5 | W29: 6 | X29: 7 | Y29: 8 | Z29: 9 | AP29: Inversa
B30: Schinus terebinthifolia | C30: 47.5 | D30: 49 | E30: 49.6 | F30: =IF(C30="", "", C30/PI()) -> 15.11972 | G30: =IF(D30="", "", D30/PI()) -> 15.597184 | H30: =IF(E30="", "", E30/PI()) -> 15.78817 | K30: =_xlfn.XLOOKUP(F30,Ref!$B$3:$B$12,Ref!$C$3:$C$12,"",1) -> 1 | L30: =_xlfn.XLOOKUP(G30,Ref!$B$3:$B$12,Ref!$C$3:$C$12,"",1) -> 1 | M30: =_xlfn.XLOOKUP(H30,Ref!$B$3:$B$12,Ref!$C$3:$C$12,"",1) -> 1 | Q30: 1 | R30: =R14/R$5 -> 0.91603053 | S30: =S14/S$5 -> 0 | T30: =T14/T$5 -> 0 | U30: =U14/U$5 -> 0 | V30: =V14/V$5 -> 0 | W30: =W14/W$5 -> 0 | X30: =X14/X$5 -> 0 | Y30: 0 | Z30: 0 | AP30: {=MINVERSE(_xlfn.ANCHORARRAY(AP18))} -> 11.909091 | AQ30: 0 | AR30: 0 | AS30: 0 | AT30: 0 | AU30: 0 | AV30: 0 | AW30: 0 | AX30: 0
B31: Matayba elaeagnoides | C31: 34.5 | D31: 42.1 | E31: 46.6 | F31: =IF(C31="", "", C31/PI()) -> 10.981691 | G31: =IF(D31="", "", D31/PI()) -> 13.400846 | H31: =IF(E31="", "", E31/PI()) -> 14.833241 | K31: =_xlfn.XLOOKUP(F31,Ref!$B$3:$B$12,Ref!$C$3:$C$12,"",1) -> 1 | L31: =_xlfn.XLOOKUP(G31,Ref!$B$3:$B$12,Ref!$C$3:$C$12,"",1) -> 1 | M31: =_xlfn.XLOOKUP(H31,Ref!$B$3:$B$12,Ref!$C$3:$C$12,"",1) -> 1 | Q31: 2 | R31: =R15/R$5 -> 0.047328244 | S31: =S15/S$5 -> 0.91304348 | T31: =T15/T$5 -> 0.016129032 | U31: =U15/U$5 -> 0 | V31: =V15/V$5 -> 0 | W31: =W15/W$5 -> 0 | X31: =X15/X$5 -> 0 | Y31: 0 | Z31: 0 | AP31: 8.838843 | AQ31: 15.681818 | AR31: 5.2272727 | AS31: 0 | AT31: 0 | AU31: 0 | AV31: 0 | AW31: 0 | AX31: 0
B32: Schinus terebinthifolia | C32: 43.7 | D32: 45.2 | E32: 45.5 | F32: =IF(C32="", "", C32/PI()) -> 13.910142 | G32: =IF(D32="", "", D32/PI()) -> 14.387607 | H32: =IF(E32="", "", E32/PI()) -> 14.4831 | K32: =_xlfn.XLOOKUP(F32,Ref!$B$3:$B$12,Ref!$C$3:$C$12,"",1) -> 1 | L32: =_xlfn.XLOOKUP(G32,Ref!$B$3:$B$12,Ref!$C$3:$C$12,"",1) -> 1 | M32: =_xlfn.XLOOKUP(H32,Ref!$B$3:$B$12,Ref!$C$3:$C$12,"",1) -> 1 | Q32: 3 | R32: =R16/R$5 -> 0 | S32: =S16/S$5 -> 0.069565217 | T32: =T16/T$5 -> 0.9516129 | U32: =U16/U$5 -> 0 | V32: =V16/V$5 -> 0 | W32: =W16/W$5 -> 0 | X32: =X16/X$5 -> 0 | Y32: 0 | Z32: 0 | AP32: 12.707438 | AQ32: 22.545455 | AR32: 28.181818 | AS32: 0 | AT32: 0 | AU32: 0 | AV32: 0 | AW32: 0 | AX32: 0
B33: Schinus terebinthifolia | C33: 37.1 | D33: 37.2 | E33: 36.5 | F33: =IF(C33="", "", C33/PI()) -> 11.809297 | G33: =IF(D33="", "", D33/PI()) -> 11.841128 | H33: =IF(E33="", "", E33/PI()) -> 11.618311 | K33: =_xlfn.XLOOKUP(F33,Ref!$B$3:$B$12,Ref!$C$3:$C$12,"",1) -> 1 | L33: =_xlfn.XLOOKUP(G33,Ref!$B$3:$B$12,Ref!$C$3:$C$12,"",1) -> 1 | M33: =_xlfn.XLOOKUP(H33,Ref!$B$3:$B$12,Ref!$C$3:$C$12,"",1) -> 1 | Q33: 4 | R33: =R17/R$5 -> 0 | S33: =S17/S$5 -> 0 | T33: =T17/T$5 -> 0.016129032 | U33: =U17/U$5 -> 0.83333333 | V33: =V17/V$5 -> 0 | W33: =W17/W$5 -> 0 | X33: =X17/X$5 -> 0 | Y33: 0 | Z33: 0 | AP33: 1.2297521 | AQ33: 2.1818182 | AR33: 2.7272727 | AS33: 6 | AT33: 0 | AU33: 0 | AV33: 0 | AW33: 0 | AX33: 0
B34: Luehea divaricata | C34: 51.9 | D34: 57.8 | E34: 63.5 | F34: =IF(C34="", "", C34/PI()) -> 16.520283 | G34: =IF(D34="", "", D34/PI()) -> 18.398311 | H34: =IF(E34="", "", E34/PI()) -> 20.212678 | K34: =_xlfn.XLOOKUP(F34,Ref!$B$3:$B$12,Ref!$C$3:$C$12,"",1) -> 1 | L34: =_xlfn.XLOOKUP(G34,Ref!$B$3:$B$12,Ref!$C$3:$C$12,"",1) -> 1 | M34: =_xlfn.XLOOKUP(H34,Ref!$B$3:$B$12,Ref!$C$3:$C$12,"",1) -> 2 | Q34: 5 | R34: =R18/R$5 -> 0 | S34: =S18/S$5 -> 0 | T34: =T18/T$5 -> 0 | U34: =U18/U$5 -> 0.16666667 | V34: =V18/V$5 -> 0.82352941 | W34: =W18/W$5 -> 0 | X34: =X18/X$5 -> 0 | Y34: 0 | Z34: 0 | AP34: 1.1614325 | AQ34: 2.0606061 | AR34: 2.5757576 | AS34: 5.6666667 | AT34: 5.6666667 | AU34: 0 | AV34: 0 | AW34: 0 | AX34: 0
B35: Ocotea puberula | C35: 87.1 | D35: 93.7 | E35: 98.1 | F35: =IF(C35="", "", C35/PI()) -> 27.724791 | G35: =IF(D35="", "", D35/PI()) -> 29.825636 | H35: =IF(E35="", "", E35/PI()) -> 31.2262 | K35: =_xlfn.XLOOKUP(F35,Ref!$B$3:$B$12,Ref!$C$3:$C$12,"",1) -> 2 | L35: =_xlfn.XLOOKUP(G35,Ref!$B$3:$B$12,Ref!$C$3:$C$12,"",1) -> 2 | M35: =_xlfn.XLOOKUP(H35,Ref!$B$3:$B$12,Ref!$C$3:$C$12,"",1) -> 3 | Q35: 6 | R35: =R19/R$5 -> 0 | S35: =S19/S$5 -> 0 | T35: =T19/T$5 -> 0 | U35: =U19/U$5 -> 0 | V35: =V19/V$5 -> 0.17647059 | W35: =W19/W$5 -> 0.94736842 | X35: =X19/X$5 -> 0 | Y35: 0 | Z35: 0 | AP35: 3.8942149 | AQ35: 6.9090909 | AR35: 8.6363636 | AS35: 19 | AT35: 19 | AU35: 19 | AV35: 0 | AW35: 0 | AX35: 0
B36: Duranta vestita | C36: 33.3 | D36: 34.6 | E36: 34.7 | F36: =IF(C36="", "", C36/PI()) -> 10.599719 | G36: =IF(D36="", "", D36/PI()) -> 11.013522 | H36: =IF(E36="", "", E36/PI()) -> 11.045353 | K36: =_xlfn.XLOOKUP(F36,Ref!$B$3:$B$12,Ref!$C$3:$C$12,"",1) -> 1 | L36: =_xlfn.XLOOKUP(G36,Ref!$B$3:$B$12,Ref!$C$3:$C$12,"",1) -> 1 | M36: =_xlfn.XLOOKUP(H36,Ref!$B$3:$B$12,Ref!$C$3:$C$12,"",1) -> 1 | Q36: 7 | R36: =R20/R$5 -> 0 | S36: =S20/S$5 -> 0 | T36: =T20/T$5 -> 0 | U36: =U20/U$5 -> 0 | V36: =V20/V$5 -> 0 | W36: =W20/W$5 -> 0.052631579 | X36: =X20/X$5 -> 0.66666667 | Y36: 0 | Z36: 0 | AP36: 0.61487603 | AQ36: 1.0909091 | AR36: 1.3636364 | AS36: 3 | AT36: 3 | AU36: 3 | AV36: 3 | AW36: 0 | AX36: 0
B37: Casearia sylvestris | C37: 58.8 | D37: 52.2 | E37: 51.5 | F37: =IF(C37="", "", C37/PI()) -> 18.716621 | G37: =IF(D37="", "", D37/PI()) -> 16.615776 | H37: =IF(E37="", "", E37/PI()) -> 16.392959 | K37: =_xlfn.XLOOKUP(F37,Ref!$B$3:$B$12,Ref!$C$3:$C$12,"",1) -> 1 | L37: =_xlfn.XLOOKUP(G37,Ref!$B$3:$B$12,Ref!$C$3:$C$12,"",1) -> 1 | M37: =_xlfn.XLOOKUP(H37,Ref!$B$3:$B$12,Ref!$C$3:$C$12,"",1) -> 1 | Q37: 8 | R37: =R21/R$5 -> 0 | S37: =S21/S$5 -> 0 | T37: =T21/T$5 -> 0 | U37: =U21/U$5 -> 0 | V37: =V21/V$5 -> 0 | W37: =W21/W$5 -> 0 | X37: =X21/X$5 -> 0.33333333 | Y37: 0.5 | Z37: 0 | AP37: 0.40991736 | AQ37: 0.72727273 | AR37: 0.90909091 | AS37: 2 | AT37: 2 | AU37: 2 | AV37: 2 | AW37: 2 | AX37: 0
B38: Ocotea puberula | C38: 32.1 | D38: 36.5 | E38: 43.1 | F38: =IF(C38="", "", C38/PI()) -> 10.217747 | G38: =IF(D38="", "", D38/PI()) -> 11.618311 | H38: =IF(E38="", "", E38/PI()) -> 13.719156 | K38: =_xlfn.XLOOKUP(F38,Ref!$B$3:$B$12,Ref!$C$3:$C$12,"",1) -> 1 | L38: =_xlfn.XLOOKUP(G38,Ref!$B$3:$B$12,Ref!$C$3:$C$12,"",1) -> 1 | M38: =_xlfn.XLOOKUP(H38,Ref!$B$3:$B$12,Ref!$C$3:$C$12,"",1) -> 1 | Q38: 9 | R38: =R22/R$5 -> 0 | S38: =S22/S$5 -> 0 | T38: =T22/T$5 -> 0 | U38: =U22/U$5 -> 0 | V38: =V22/V$5 -> 0 | W38: =W22/W$5 -> 0 | X38: =X22/X$5 -> 0 | Y38: 0 | Z38: 0 | AP38: 0 | AQ38: 0 | AR38: 0 | AS38: 0 | AT38: 0 | AU38: 0 | AV38: 0 | AW38: 0 | AX38: 1
B39: Schinus terebinthifolia | C39: 48.3 | D39: 0 | E39: 50.3 | F39: =IF(C39="", "", C39/PI()) -> 15.374368 | G39: =IF(D39="", "", D39/PI()) -> 0 | H39: =IF(E39="", "", E39/PI()) -> 16.010987 | K39: =_xlfn.XLOOKUP(F39,Ref!$B$3:$B$12,Ref!$C$3:$C$12,"",1) -> 1 | L39: =_xlfn.XLOOKUP(G39,Ref!$B$3:$B$12,Ref!$C$3:$C$12,"",1) -> Morta | M39: =_xlfn.XLOOKUP(H39,Ref!$B$3:$B$12,Ref!$C$3:$C$12,"",1) -> 1
B40: Gymnanthes klotzschiana | C40: 45.8 | D40: 49 | E40: 52.1 | F40: =IF(C40="", "", C40/PI()) -> 14.578593 | G40: =IF(D40="", "", D40/PI()) -> 15.597184 | H40: =IF(E40="", "", E40/PI()) -> 16.583945 | K40: =_xlfn.XLOOKUP(F40,Ref!$B$3:$B$12,Ref!$C$3:$C$12,"",1) -> 1 | L40: =_xlfn.XLOOKUP(G40,Ref!$B$3:$B$12,Ref!$C$3:$C$12,"",1) -> 1 | M40: =_xlfn.XLOOKUP(H40,Ref!$B$3:$B$12,Ref!$C$3:$C$12,"",1) -> 1
B41: Gymnanthes klotzschiana | C41: 49.4 | D41: 55.5 | E41: 60.7 | F41: =IF(C41="", "", C41/PI()) -> 15.724508 | G41: =IF(D41="", "", D41/PI()) -> 17.666199 | H41: =IF(E41="", "", E41/PI()) -> 19.32141 | K41: =_xlfn.XLOOKUP(F41,Ref!$B$3:$B$12,Ref!$C$3:$C$12,"",1) -> 1 | L41: =_xlfn.XLOOKUP(G41,Ref!$B$3:$B$12,Ref!$C$3:$C$12,"",1) -> 1 | M41: =_xlfn.XLOOKUP(H41,Ref!$B$3:$B$12,Ref!$C$3:$C$12,"",1) -> 1
...
